Traceback (most recent call last):
  File "/home/kalicem/RetroPie-Manager/manage.py", line 10, in <module>
    execute_from_command_line(sys.argv)
  File "/home/kalicem/RetroPie-Manager/venv/lib/python3.12/site-packages/django/core/management/__init__.py", line 419, in execute_from_command_line
    utility.execute()
  File "/home/kalicem/RetroPie-Manager/venv/lib/python3.12/site-packages/django/core/management/__init__.py", line 413, in execute
    self.fetch_command(subcommand).run_from_argv(self.argv)
  File "/home/kalicem/RetroPie-Manager/venv/lib/python3.12/site-packages/django/core/management/base.py", line 354, in run_from_argv
    self.execute(*args, **cmd_options)
  File "/home/kalicem/RetroPie-Manager/venv/lib/python3.12/site-packages/django/core/management/base.py", line 398, in execute
    output = self.handle(*args, **options)
             ^^^^^^^^^^^^^^^^^^^^^^^^^^^^^
  File "/home/kalicem/RetroPie-Manager/venv/lib/python3.12/site-packages/django/core/management/base.py", line 89, in wrapped
    res = handle_func(*args, **kwargs)
          ^^^^^^^^^^^^^^^^^^^^^^^^^^^^
  File "/home/kalicem/RetroPie-Manager/venv/lib/python3.12/site-packages/django/core/management/commands/migrate.py", line 75, in handle
    self.check(databases=[database])
  File "/home/kalicem/RetroPie-Manager/venv/lib/python3.12/site-packages/django/core/management/base.py", line 419, in check
    all_issues = checks.run_checks(
                 ^^^^^^^^^^^^^^^^^^
  File "/home/kalicem/RetroPie-Manager/venv/lib/python3.12/site-packages/django/core/checks/registry.py", line 76, in run_checks
    new_errors = check(app_configs=app_configs, databases=databases)
                 ^^^^^^^^^^^^^^^^^^^^^^^^^^^^^^^^^^^^^^^^^^^^^^^^^^^
  File "/home/kalicem/RetroPie-Manager/venv/lib/python3.12/site-packages/django/core/checks/urls.py", line 13, in check_url_config
    return check_resolver(resolver)
           ^^^^^^^^^^^^^^^^^^^^^^^^
  File "/home/kalicem/RetroPie-Manager/venv/lib/python3.12/site-packages/django/core/checks/urls.py", line 23, in check_resolver
    return check_method()
           ^^^^^^^^^^^^^^
  File "/home/kalicem/RetroPie-Manager/venv/lib/python3.12/site-packages/django/urls/resolvers.py", line 416, in check
    for pattern in self.url_patterns:
                   ^^^^^^^^^^^^^^^^^
  File "/home/kalicem/RetroPie-Manager/venv/lib/python3.12/site-packages/django/utils/functional.py", line 48, in __get__
    res = instance.__dict__[self.name] = self.func(instance)
                                         ^^^^^^^^^^^^^^^^^^^
  File "/home/kalicem/RetroPie-Manager/venv/lib/python3.12/site-packages/django/urls/resolvers.py", line 602, in url_patterns
    patterns = getattr(self.urlconf_module, "urlpatterns", self.urlconf_module)
                       ^^^^^^^^^^^^^^^^^^^
  File "/home/kalicem/RetroPie-Manager/venv/lib/python3.12/site-packages/django/utils/functional.py", line 48, in __get__
    res = instance.__dict__[self.name] = self.func(instance)
                                         ^^^^^^^^^^^^^^^^^^^
  File "/home/kalicem/RetroPie-Manager/venv/lib/python3.12/site-packages/django/urls/resolvers.py", line 595, in urlconf_module
    return import_module(self.urlconf_name)
           ^^^^^^^^^^^^^^^^^^^^^^^^^^^^^^^^
  File "/usr/lib/python3.12/importlib/__init__.py", line 90, in import_module
    return _bootstrap._gcd_import(name[level:], package, level)
           ^^^^^^^^^^^^^^^^^^^^^^^^^^^^^^^^^^^^^^^^^^^^^^^^^^^^
  File "<frozen importlib._bootstrap>", line 1387, in _gcd_import
  File "<frozen importlib._bootstrap>", line 1360, in _find_and_load
  File "<frozen importlib._bootstrap>", line 1331, in _find_and_load_unlocked
  File "<frozen importlib._bootstrap>", line 935, in _load_unlocked
  File "<frozen importlib._bootstrap_external>", line 995, in exec_module
  File "<frozen importlib._bootstrap>", line 488, in _call_with_frames_removed
  File "/home/kalicem/RetroPie-Manager/project/urls.py", line 17, in <module>
    from django.conf.urls import patterns, include, url
ImportError: cannot import name 'patterns' from 'django.conf.urls' (/home/kalicem/RetroPie-Manager/venv/lib/python3.12/site-packages/django/conf/urls/__init__.py)
make: *** [Makefile:31 : install] Erreur 1
